Workbook
Name ANR: コスト!$A$1:$E$41
Name ANR: '1'!$B$4:$D$359
Name SN: [1]揚水発電ユニット!$C$2:$C$119
Name SN: '7'!$C$2:$C$119
Name time: #REF!
Name time: #REF!
Name time: #REF!
Name time: #REF!

Sheet Contents
A1: シート | B1: 内容 | C1: Data Source | D1: PyPSA | F1: V1
A2: carriers | D2: 〇 | F2: V2 | G2: 揚水発電所追加
A3: buses | D3: 〇 | F3: V3 | G3: 揚水発電所と水力が重複していたため、水力から重複を削除
A4: links | D4: 〇 | F4: V4 | G4: 原子力発電所の稼働状態を反映
A5: generators | D5: 〇 | F5: V5 | G5: 揚水発電所のサイクル効率を0.7に設定
A6: loads | D6: 〇
A7: Demand | B7: 2024年の電力需要 | C7: OCCTO | D7: 〇
A8: stores | D8: 〇
A9: コスト | B9: 入力用シート。Generatorsに反映される
A10: 変電所対応表 | B10: 変電所と電力会社のリンク
A16: 関係のないシートは日本語にしておくこと。読み取りの時にキーワードがあると読み込まれてしまう。
A18: 1 | B18: 変電所リスト
A19: 2 | B19: 揚水発電所のバス
A20: 3 | B20: コストの設定用シート
A21: 4 | B21: PyPSAのStoreシート
A22: 5 | B22: 貯水池の設定用シート
A23: 6 | B23: 揚水発電所の発電機（links)
A24: 7 | B24: 揚水発電ユニット一覧（OPGMより）
C27: https://www.meti.go.jp/shingikai/enecho/denryoku_gas/saisei_kano/smart_power_grid_wg/pdf/003_01_00.pdf

Sheet コスト
A1: 電源種別 | B1: type | C1: capital_cost | D1: marginal_cost | E1: p_max_pu | F1: lifetime
A2: 火力（石油） | B2: oil | C2: =145*1000 -> 145000 | D2: 17500 | E2: 1 | F2: 40
A3: 火力（ガス） | B3: cas | C3: =170*1000 -> 170000 | D3: 12500 | E3: 1 | F3: 40
A4: 火力（石炭） | B4: coal | C4: =270*1000 -> 270000 | D4: =8.5*1000 -> 8500 | E4: 1 | F4: 40
A5: 原子力 | B5: nuclear | C5: =400000 -> 400000 | D5: 2000 | E5: 1 | F5: 60
A6: バイオマス | B6: biomass | C6: 145000 | D6: 17500 | E6: 1 | F6: 40
A7: 水力 | B7: hydro | C7: 400000 | D7: 2000 | E7: 0.53 | F7: 60
A8: 太陽光 | B8: solar | C8: 200000 | D8: 0 | E8: 0 | F8: 30
A9: 風力 | B9: wind | C9: 200000 | D9: 0 | E9: 0 | F9: 30
A10: その他 | B10: other | C10: =145*1000 -> 145000 | D10: 17500 | E10: 0 | F10: 30

Sheet carriers
A1: name | B1: co2_emissions
A2: AC | B2: 0
A3: DC | B3: 0
A4: 火力（石炭） | B4: 0
A5: 火力（ガス） | B5: 0
A6: 火力（石油） | B6: 0
A7: 水力 | B7: 0
A8: 太陽光 | B8: 0
A9: 風力 | B9: 0
A10: 原子力 | B10: 0
A11: バイオマス | B11: 0
A12: その他 | B12: 0
A13: 揚水（充電） | B13: 0
... A15: 水 | B15: 0

Sheet buses
A1: name | B1: carrier | C1: x | D1: y
A2: 北海道 | B2: AC | C2: 141.4 | D2: 43.07
A3: 東北 | B3: AC | C3: 140.91 | D3: 38.28
A4: 東京 | B4: AC | C4: 139.82 | D4: 35.67
A5: 中部 | B5: AC | C5: 137.01 | D5: 35.18
A6: 北陸 | B6: AC | C6: 137.22 | D6: 36.7
A7: 関西 | B7: AC | C7: 135.95 | D7: 34.73
A8: 中国 | B8: AC | C8: 132.46 | D8: 34.39
A9: 四国 | B9: AC | C9: 134.05 | D9: 34.35
A10: 九州 | B10: AC | C10: 130.41 | D10: 33.58
A11: 新冠 | B11: 水 | C11: 142.59293 | D11: 42.617294
A12: 高見 | B12: 水 | C12: 142.63493 | D12: 42.456129
A13: 京極 | B13: 水 | C13: 140.95692 | D13: 42.959215
... A50: 小丸川 | B50: 水 | C50: 131.39287 | D50: 32.250725

Sheet links
A1: name | B1: carrier | C1: bus0 | D1: bus1 | E1: bus2 | F1: p_nom | G1: efficiency | H1: marginal_cost | I1: capital_cost | J1: p_max_pu | K1: p_min_pu | L1: committable | M1: min_up_time | N1: p_nom_extendable | O1: ramp_limit_down | P1: ramp_limit_up | Q1: start_up_cost
A2: 北海道本州連系設備 | B2: DC | C2: 北海道 | D2: 東北 | F2: 900 | G2: 1 | H2: 0 | I2: 1 | J2: 1 | K2: -1 | L2: FALSE | M2: 0 | N2: FALSE | O2: 1 | P2: 1 | Q2: 0
A3: 東北東京間連系線 | B3: AC | C3: 東北 | D3: 東京 | F3: 2360 | G3: 1 | H3: 0 | I3: 1 | J3: 1 | K3: -1 | L3: FALSE | M3: 0 | N3: FALSE | O3: 1 | P3: 1 | Q3: 0
A4: 東京中部間連系線 | B4: DC | C4: 東京 | D4: 中部 | F4: 2100 | G4: 1 | H4: 0 | I4: 1 | J4: 1 | K4: -1 | L4: FALSE | M4: 0 | N4: FALSE | O4: 1 | P4: 1 | Q4: 0
A5: 中部北陸連系設備 | B5: DC | C5: 中部 | D5: 北陸 | F5: 300 | G5: 1 | H5: 0 | I5: 1 | J5: 1 | K5: -1 | L5: FALSE | M5: 0 | N5: FALSE | O5: 1 | P5: 1 | Q5: 0
A6: 中部関西連系線 | B6: AC | C6: 中部 | D6: 関西 | F6: 2500 | G6: 1 | H6: 0 | I6: 1 | J6: 0.464 | K6: -1 | L6: FALSE | M6: 0 | N6: FALSE | O6: 1 | P6: 1 | Q6: 0
A7: 北陸関西連系線 | B7: AC | C7: 北陸 | D7: 関西 | F7: 1900 | G7: 1 | H7: 0 | I7: 1 | J7: 1 | K7: -0.789 | L7: FALSE | M7: 0 | N7: FALSE | O7: 1 | P7: 1 | Q7: 0
A8: 関西中国間連系線 | B8: AC | C8: 関西 | D8: 中国 | F8: 4550 | G8: 1 | H8: 0 | I8: 1 | J8: 0.611 | K8: -1 | L8: FALSE | M8: 0 | N8: FALSE | O8: 1 | P8: 1 | Q8: 0
A9: 関西四国間連系設備 | B9: DC | C9: 関西 | D9: 四国 | F9: 1400 | G9: 1 | H9: 0 | I9: 1 | J9: 1 | K9: -1 | L9: FALSE | M9: 0 | N9: FALSE | O9: 1 | P9: 1 | Q9: 0
A10: 中国四国間連系線 | B10: AC | C10: 中国 | D10: 四国 | F10: 1200 | G10: 1 | H10: 0 | I10: 1 | J10: 1 | K10: -1 | L10: FALSE | M10: 0 | N10: FALSE | O10: 1 | P10: 1 | Q10: 0
A11: 中国九州間連系線 | B11: AC | C11: 中国 | D11: 九州 | F11: 2470 | G11: 1 | H11: 0 | I11: 1 | J11: 0.093 | K11: -1 | L11: FALSE | M11: 0 | N11: FALSE | O11: 1 | P11: 1 | Q11: 0
A12: 新冠(充電) | B12: 揚水（充電） | C12: 北海道 | D12: 新冠 | F12: 200 | G12: 0.92 | H12: 0 | I12: 1 | J12: 1 | K12: 0 | L12: FALSE | M12: 0 | N12: FALSE | O12: 1 | P12: 1 | Q12: 0
A13: 高見(充電) | B13: 揚水（充電） | C13: 北海道 | D13: 高見 | F13: 200 | G13: 0.92 | H13: 0 | I13: 1 | J13: 1 | K13: 0 | L13: FALSE | M13: 0 | N13: FALSE | O13: 1 | P13: 1 | Q13: 0
... A51: 小丸川(充電) | B51: 揚水（充電） | C51: 九州 | D51: 小丸川 | F51: 1200 | G51: 0.92 | H51: 0 | I51: 1 | J51: 1 | K51: 0 | L51: FALSE | M51: 0 | N51: FALSE | O51: 1 | P51: 1 | Q51: 0
A52: =テーブル3[[#This Row],[name]]&#REF! -> 新冠(放電) | B52: 揚水（放電） | C52: 新冠 | D52: 北海道 | F52: 200 | G52: 0.92 | H52: 0 | I52: 1 | J52: 1 | K52: 0 | L52: FALSE | M52: 0 | N52: FALSE | O52: 1 | P52: 1 | Q52: 0
A53: =テーブル3[[#This Row],[name]]&#REF! -> 高見(放電) | B53: 揚水（放電） | C53: 高見 | D53: 北海道 | F53: 200 | G53: 0.92 | H53: 0 | I53: 1 | J53: 1 | K53: 0 | L53: FALSE | M53: 0 | N53: FALSE | O53: 1 | P53: 1 | Q53: 0
A54: =テーブル3[[#This Row],[name]]&#REF! -> 京極(放電) | B54: 揚水（放電） | C54: 京極 | D54: 北海道 | F54: 400 | G54: 0.92 | H54: 0 | I54: 1 | J54: 1 | K54: 0 | L54: FALSE | M54: 0 | N54: FALSE | O54: 1 | P54: 1 | Q54: 0
A55: =テーブル3[[#This Row],[name]]&#REF! -> 第二沼沢(放電) | B55: 揚水（放電） | C55: 第二沼沢 | D55: 東北 | F55: 460 | G55: 0.92 | H55: 0 | I55: 1 | J55: 1 | K55: 0 | L55: FALSE | M55: 0 | N55: FALSE | O55: 1 | P55: 1 | Q55: 0
A56: =テーブル3[[#This Row],[name]]&#REF! -> 今市(放電) | B56: 揚水（放電） | C56: 今市 | D56: 東京 | F56: 1050 | G56: 0.92 | H56: 0 | I56: 1 | J56: 1 | K56: 0 | L56: FALSE | M56: 0 | N56: FALSE | O56: 1 | P56: 1 | Q56: 0
A57: =テーブル3[[#This Row],[name]]&#REF! -> 矢木沢(放電) | B57: 揚水（放電） | C57: 矢木沢 | D57: 東京 | F57: 240 | G57: 0.92 | H57: 0 | I57: 1 | J57: 1 | K57: 0 | L57: FALSE | M57: 0 | N57: FALSE | O57: 1 | P57: 1 | Q57: 0
A58: =テーブル3[[#This Row],[name]]&#REF! -> 玉原(放電) | B58: 揚水（放電） | C58: 玉原 | D58: 東京 | F58: 1200 | G58: 0.92 | H58: 0 | I58: 1 | J58: 1 | K58: 0 | L58: FALSE | M58: 0 | N58: FALSE | O58: 1 | P58: 1 | Q58: 0
A59: =テーブル3[[#This Row],[name]]&#REF! -> 塩原(放電) | B59: 揚水（放電） | C59: 塩原 | D59: 東京 | F59: 900 | G59: 0.92 | H59: 0 | I59: 1 | J59: 1 | K59: 0 | L59: FALSE | M59: 0 | N59: FALSE | O59: 1 | P59: 1 | Q59: 0
A60: =テーブル3[[#This Row],[name]]&#REF! -> 安曇(放電) | B60: 揚水（放電） | C60: 安曇 | D60: 東京 | F60: 623 | G60: 0.92 | H60: 0 | I60: 1 | J60: 1 | K60: 0 | L60: FALSE | M60: 0 | N60: FALSE | O60: 1 | P60: 1 | Q60: 0
A61: =テーブル3[[#This Row],[name]]&#REF! -> 水殿(放電) | B61: 揚水（放電） | C61: 水殿 | D61: 東京 | F61: 163 | G61: 0.92 | H61: 0 | I61: 1 | J61: 1 | K61: 0 | L61: FALSE | M61: 0 | N61: FALSE | O61: 1 | P61: 1 | Q61: 0
A62: =テーブル3[[#This Row],[name]]&#REF! -> 新高瀬川(放電) | B62: 揚水（放電） | C62: 新高瀬川 | D62: 東京 | F62: 1280 | G62: 0.92 | H62: 0 | I62: 1 | J62: 1 | K62: 0 | L62: FALSE | M62: 0 | N62: FALSE | O62: 1 | P62: 1 | Q62: 0
A63: =テーブル3[[#This Row],[name]]&#REF! -> 葛野川(放電) | B63: 揚水（放電） | C63: 葛野川 | D63: 東京 | F63: 1200 | G63: 0.92 | H63: 0 | I63: 1 | J63: 1 | K63: 0 | L63: FALSE | M63: 0 | N63: FALSE | O63: 1 | P63: 1 | Q63: 0
... A91: =テーブル3[[#This Row],[name]]&#REF! -> 小丸川(放電) | B91: 揚水（放電） | C91: 小丸川 | D91: 九州 | F91: 1200 | G91: 0.92 | H91: 0 | I91: 1 | J91: 1 | K91: 0 | L91: FALSE | M91: 0 | N91: FALSE | O91: 1 | P91: 1 | Q91: 0

Sheet generators
A1: name | B1: bus | C1: carrier | D1: efficiency | E1: capital_cost | F1: marginal_cost | G1: p_nom | H1: p_max_pu | I1: p_min_pu | J1: min_up_time | K1: committable | L1: p_nom_extendable | M1: ramp_limit_up | N1: ramp_limit_down | O1: y | P1: x
A2: 鹿島火力発電所 | B2: 東京 | C2: 火力（石炭） | D2: 1 | E2: =VLOOKUP(C2,'[1]3'!$A$2:$D$11,3,FALSE) -> 270000 | F2: =VLOOKUP(C2,'[1]3'!$A$2:$D$11,4,FALSE) -> 8500 | G2: 1905 | H2: =VLOOKUP(C2,'[1]3'!$A$2:$E$11,5,FALSE) -> 1 | I2: 0 | J2: 0 | K2: FALSE | L2: FALSE | M2: 1 | N2: 1 | O2: 35.916287 | P2: 140.7013
A3: 千葉火力発電所 | B3: 東京 | C3: 火力（ガス） | D3: 1 | E3: =VLOOKUP(C3,'[1]3'!$A$2:$D$11,3,FALSE) -> 170000 | F3: =VLOOKUP(C3,'[1]3'!$A$2:$D$11,4,FALSE) -> 12500 | G3: 4380 | H3: =VLOOKUP(C3,'[1]3'!$A$2:$E$11,5,FALSE) -> 1 | I3: 0 | J3: 0 | K3: FALSE | L3: FALSE | M3: 1 | N3: 1 | O3: 35.564881 | P3: 140.10722
A4: 五井火力発電所 | B4: 東京 | C4: 火力（ガス） | D4: 1 | E4: =VLOOKUP(C4,'[1]3'!$A$2:$D$11,3,FALSE) -> 170000 | F4: =VLOOKUP(C4,'[1]3'!$A$2:$D$11,4,FALSE) -> 12500 | G4: 2340 | H4: =VLOOKUP(C4,'[1]3'!$A$2:$E$11,5,FALSE) -> 1 | I4: 0 | J4: 0 | K4: FALSE | L4: FALSE | M4: 1 | N4: 1 | O4: 35.546898 | P4: 140.07191
A5: 姉崎火力発電所 | B5: 東京 | C5: 火力（ガス） | D5: 1 | E5: =VLOOKUP(C5,'[1]3'!$A$2:$D$11,3,FALSE) -> 170000 | F5: =VLOOKUP(C5,'[1]3'!$A$2:$D$11,4,FALSE) -> 12500 | G5: 3140.7 | H5: =VLOOKUP(C5,'[1]3'!$A$2:$E$11,5,FALSE) -> 1 | I5: 0 | J5: 0 | K5: =K4 -> FALSE | L5: FALSE | M5: 1 | N5: 1 | O5: 35.485048 | P5: 140.0174
A6: 富津火力発電所 | B6: 東京 | C6: 火力（ガス） | D6: 1 | E6: =VLOOKUP(C6,'[1]3'!$A$2:$D$11,3,FALSE) -> 170000 | F6: =VLOOKUP(C6,'[1]3'!$A$2:$D$11,4,FALSE) -> 12500 | G6: 5342 | H6: =VLOOKUP(C6,'[1]3'!$A$2:$E$11,5,FALSE) -> 1 | I6: 0 | J6: 0 | K6: =K5 -> FALSE | L6: FALSE | M6: 1 | N6: 1 | O6: 35.342406 | P6: 139.83222
A7: 横須賀火力発電所 | B7: 東京 | C7: 火力（石炭） | D7: 1 | E7: =VLOOKUP(C7,'[1]3'!$A$2:$D$11,3,FALSE) -> 270000 | F7: =VLOOKUP(C7,'[1]3'!$A$2:$D$11,4,FALSE) -> 8500 | G7: 1300 | H7: =VLOOKUP(C7,'[1]3'!$A$2:$E$11,5,FALSE) -> 1 | I7: 0 | J7: 0 | K7: =K6 -> FALSE | L7: FALSE | M7: 1 | N7: 1 | O7: 35.215743 | P7: 139.71651
A8: 知多第二火力発電所 | B8: 中部 | C8: 火力（ガス） | D8: 1 | E8: =VLOOKUP(C8,'[1]3'!$A$2:$D$11,3,FALSE) -> 170000 | F8: =VLOOKUP(C8,'[1]3'!$A$2:$D$11,4,FALSE) -> 12500 | G8: 1708 | H8: =VLOOKUP(C8,'[1]3'!$A$2:$E$11,5,FALSE) -> 1 | I8: 0 | J8: 0 | K8: =K7 -> FALSE | L8: FALSE | M8: 1 | N8: 1 | O8: 35.005808 | P8: 136.86363
A9: 渥美火力発電所 | B9: 中部 | C9: 火力（石油） | D9: 1 | E9: =VLOOKUP(C9,'[1]3'!$A$2:$D$11,3,FALSE) -> 145000 | F9: =VLOOKUP(C9,'[1]3'!$A$2:$D$11,4,FALSE) -> 17500 | G9: 1400 | H9: =VLOOKUP(C9,'[1]3'!$A$2:$E$11,5,FALSE) -> 1 | I9: 0 | J9: 0 | K9: =K8 -> FALSE | L9: FALSE | M9: 1 | N9: 1 | O9: 34.654697 | P9: 137.06672
A10: 常陸那珂共同火力発電所 | B10: 東京 | C10: 火力（石炭） | D10: 1 | E10: =VLOOKUP(C10,'[1]3'!$A$2:$D$11,3,FALSE) -> 270000 | F10: =VLOOKUP(C10,'[1]3'!$A$2:$D$11,4,FALSE) -> 8500 | G10: 650 | H10: =VLOOKUP(C10,'[1]3'!$A$2:$E$11,5,FALSE) -> 1 | I10: 0 | J10: 0 | K10: =K9 -> FALSE | L10: FALSE | M10: 1 | N10: 1 | O10: 36.437109 | P10: 140.61688
A11: 西名古屋火力発電所 | B11: 中部 | C11: 火力（ガス） | D11: 1 | E11: =VLOOKUP(C11,'[1]3'!$A$2:$D$11,3,FALSE) -> 170000 | F11: =VLOOKUP(C11,'[1]3'!$A$2:$D$11,4,FALSE) -> 12500 | G11: 2376.4 | H11: =VLOOKUP(C11,'[1]3'!$A$2:$E$11,5,FALSE) -> 1 | I11: 0 | J11: 0 | K11: =K10 -> FALSE | L11: FALSE | M11: 1 | N11: 1 | O11: 35.032248 | P11: 136.83119
A12: 常陸那珂火力発電所 | B12: 東京 | C12: 火力（石炭） | D12: 1 | E12: =VLOOKUP(C12,'[1]3'!$A$2:$D$11,3,FALSE) -> 270000 | F12: =VLOOKUP(C12,'[1]3'!$A$2:$D$11,4,FALSE) -> 8500 | G12: 2000 | H12: =VLOOKUP(C12,'[1]3'!$A$2:$E$11,5,FALSE) -> 1 | I12: 0 | J12: 0 | K12: =K11 -> FALSE | L12: FALSE | M12: 1 | N12: 1 | O12: 36.437954 | P12: 140.61821
A13: 知多火力発電所 | B13: 中部 | C13: 火力（ガス） | D13: 1 | E13: =VLOOKUP(C13,'[1]3'!$A$2:$D$11,3,FALSE) -> 170000 | F13: =VLOOKUP(C13,'[1]3'!$A$2:$D$11,4,FALSE) -> 12500 | G13: 1554 | H13: =VLOOKUP(C13,'[1]3'!$A$2:$E$11,5,FALSE) -> 1 | I13: 0 | J13: 0 | K13: =K12 -> FALSE | L13: FALSE | M13: 1 | N13: 1 | O13: 34.986024 | P13: 136.8451
A14: 武豊火力発電所 | B14: 中部 | C14: 火力（石炭） | D14: 1 | E14: =VLOOKUP(C14,'[1]3'!$A$2:$D$11,3,FALSE) -> 270000 | F14: =VLOOKUP(C14,'[1]3'!$A$2:$D$11,4,FALSE) -> 8500 | G14: 1070 | H14: =VLOOKUP(C14,'[1]3'!$A$2:$E$11,5,FALSE) -> 1 | I14: 0 | J14: 0 | K14: =K13 -> FALSE | L14: FALSE | M14: 1 | N14: 1 | O14: 34.823377 | P14: 136.92394
A15: 四日市火力発電所 | B15: 中部 | C15: 火力（ガス） | D15: 1 | E15: =VLOOKUP(C15,'[1]3'!$A$2:$D$11,3,FALSE) -> 170000 | F15: =VLOOKUP(C15,'[1]3'!$A$2:$D$11,4,FALSE) -> 12500 | G15: 585 | H15: =VLOOKUP(C15,'[1]3'!$A$2:$E$11,5,FALSE) -> 1 | I15: 0 | J15: 0 | K15: =K14 -> FALSE | L15: FALSE | M15: 1 | N15: 1 | O15: 34.974507 | P15: 136.64654
A16: 上越火力発電所 | B16: 東北 | C16: 火力（ガス） | D16: 1 | E16: =VLOOKUP(C16,'[1]3'!$A$2:$D$11,3,FALSE) -> 170000 | F16: =VLOOKUP(C16,'[1]3'!$A$2:$D$11,4,FALSE) -> 12500 | G16: 2380 | H16: =VLOOKUP(C16,'[1]3'!$A$2:$E$11,5,FALSE) -> 1 | I16: 0 | J16: 0 | K16: =K15 -> FALSE | L16: FALSE | M16: 1 | N16: 1 | O16: 37.20531 | P16: 138.27745
... A48: 敦賀発電所2号機 | B48: 北陸 | C48: 原子力 | D48: 1 | E48: =VLOOKUP(C48,'[1]3'!$A$2:$D$11,3,FALSE) -> 400000 | F48: =VLOOKUP(C48,'[1]3'!$A$2:$D$11,4,FALSE) -> 2000 | G48: 1160 | H48: =VLOOKUP(C48,'[1]3'!$A$2:$E$11,5,FALSE) -> 1 | I48: 0 | J48: 0 | K48: =K47 -> FALSE | L48: FALSE | M48: 0 | N48: 0 | O48: 35.752896 | P48: 136.00546
A49: 東海第二発電所 | B49: 東京 | C49: 原子力 | D49: 1 | E49: =VLOOKUP(C49,'[1]3'!$A$2:$D$11,3,FALSE) -> 400000 | F49: =VLOOKUP(C49,'[1]3'!$A$2:$D$11,4,FALSE) -> 2000 | G49: 1100 | H49: 0 | I49: 0 | J49: 0 | K49: =K48 -> FALSE | L49: FALSE | M49: 0 | N49: 0 | O49: 36.466532 | P49: 140.60736
A50: 四国電力 西条発電所 | B50: 四国 | C50: 火力（石炭） | D50: 1 | E50: =VLOOKUP(C50,'[1]3'!$A$2:$D$11,3,FALSE) -> 270000 | F50: =VLOOKUP(C50,'[1]3'!$A$2:$D$11,4,FALSE) -> 8500 | G50: 750 | H50: =VLOOKUP(C50,'[1]3'!$A$2:$E$11,5,FALSE) -> 1 | I50: 0 | J50: 0 | K50: =K49 -> FALSE | L50: FALSE | M50: 0.5 | N50: 0.5 | O50: 33.932061 | P50: 133.1684
A51: 東北電力上越火力発電所１号機 | B51: 東北 | C51: 火力（ガス） | D51: 1 | E51: =VLOOKUP(C51,'[1]3'!$A$2:$D$11,3,FALSE) -> 170000 | F51: =VLOOKUP(C51,'[1]3'!$A$2:$D$11,4,FALSE) -> 12500 | G51: 572 | H51: =VLOOKUP(C51,'[1]3'!$A$2:$E$11,5,FALSE) -> 1 | I51: 0 | J51: 0 | K51: =K50 -> FALSE | L51: FALSE | M51: 1 | N51: 1 | O51: 37.20531 | P51: 138.27745
A52: 三隅発電所第１号機 | B52: 中国 | C52: 火力（石炭） | D52: 1 | E52: =VLOOKUP(C52,'[1]3'!$A$2:$D$11,3,FALSE) -> 270000 | F52: =VLOOKUP(C52,'[1]3'!$A$2:$D$11,4,FALSE) -> 8500 | G52: 1000 | H52: =VLOOKUP(C52,'[1]3'!$A$2:$E$11,5,FALSE) -> 1 | I52: 0 | J52: 0 | K52: =K51 -> FALSE | L52: FALSE | M52: 0.5 | N52: 0.5 | O52: 34.779211 | P52: 131.92081
A53: 三隅発電所第２号機 | B53: 中国 | C53: 火力（石炭） | D53: 1 | E53: =VLOOKUP(C53,'[1]3'!$A$2:$D$11,3,FALSE) -> 270000 | F53: =VLOOKUP(C53,'[1]3'!$A$2:$D$11,4,FALSE) -> 8500 | G53: 1000 | H53: =VLOOKUP(C53,'[1]3'!$A$2:$E$11,5,FALSE) -> 1 | I53: 0 | J53: 0 | K53: =K52 -> FALSE | L53: FALSE | M53: 0.5 | N53: 0.5 | O53: 34.779211 | P53: 131.92081
A54: 鈴川エネルギーセンター発電所 | B54: 中部 | C54: 火力（石炭） | D54: 1 | E54: =VLOOKUP(C54,'[1]3'!$A$2:$D$11,3,FALSE) -> 270000 | F54: =VLOOKUP(C54,'[1]3'!$A$2:$D$11,4,FALSE) -> 8500 | G54: 112 | H54: =VLOOKUP(C54,'[1]3'!$A$2:$E$11,5,FALSE) -> 1 | I54: 0 | J54: 0 | K54: =K53 -> FALSE | L54: FALSE | M54: 0.5 | N54: 0.5 | O54: 35.143586 | P54: 138.7147
A55: トクヤマ東発電所第3号発電所 | B55: 中国 | C55: 火力（石炭） | D55: 1 | E55: =VLOOKUP(C55,'[1]3'!$A$2:$D$11,3,FALSE) -> 270000 | F55: =VLOOKUP(C55,'[1]3'!$A$2:$D$11,4,FALSE) -> 8500 | G55: 300 | H55: =VLOOKUP(C55,'[1]3'!$A$2:$E$11,5,FALSE) -> 1 | I55: 0 | J55: 0 | K55: =K54 -> FALSE | L55: FALSE | M55: 0.5 | N55: 0.5 | O55: 34.036315 | P55: 131.79464
A56: 牧港GT2号 | B56: 九州 | C56: 火力（石油） | D56: 1 | E56: =VLOOKUP(C56,'[1]3'!$A$2:$D$11,3,FALSE) -> 145000 | F56: =VLOOKUP(C56,'[1]3'!$A$2:$D$11,4,FALSE) -> 17500 | G56: 103 | H56: =VLOOKUP(C56,'[1]3'!$A$2:$E$11,5,FALSE) -> 1 | I56: 0 | J56: 0 | K56: =K55 -> FALSE | L56: FALSE | M56: 1 | N56: 1 | O56: 26.26978 | P56: 127.72114
A57: 石川GT1号 | B57: 九州 | C57: 火力（石油） | D57: 1 | E57: =VLOOKUP(C57,'[1]3'!$A$2:$D$11,3,FALSE) -> 145000 | F57: =VLOOKUP(C57,'[1]3'!$A$2:$D$11,4,FALSE) -> 17500 | G57: 103 | H57: =VLOOKUP(C57,'[1]3'!$A$2:$E$11,5,FALSE) -> 1 | I57: 0 | J57: 0 | K57: =K56 -> FALSE | L57: FALSE | M57: 1 | N57: 1 | O57: 26.429464 | P57: 127.84139
A58: 宇部興産発電所 | B58: 東京 | C58: 火力（石炭） | D58: 1 | E58: =VLOOKUP(C58,'[1]3'!$A$2:$D$11,3,FALSE) -> 270000 | F58: =VLOOKUP(C58,'[1]3'!$A$2:$D$11,4,FALSE) -> 8500 | G58: 361 | H58: =VLOOKUP(C58,'[1]3'!$A$2:$E$11,5,FALSE) -> 1 | I58: 0 | J58: 0 | K58: =K57 -> FALSE | L58: FALSE | M58: 0.5 | N58: 0.5 | O58: 36.62679 | P58: 139.89755
A59: 福島いわきバイオマス発電所 | B59: 東京 | C59: その他 | D59: 1 | E59: =VLOOKUP(C59,'[1]3'!$A$2:$D$11,3,FALSE) -> 145000 | F59: =VLOOKUP(C59,'[1]3'!$A$2:$D$11,4,FALSE) -> 17500 | G59: 112 | H59: =VLOOKUP(C59,'[1]3'!$A$2:$E$11,5,FALSE) -> 0 | I59: 0 | J59: 0 | K59: =K58 -> FALSE | L59: FALSE | M59: 1 | N59: 1 | O59: 37.080301 | P59: 140.84185
A60: ゼロワットパワー美浜発電所 | B60: 東京 | C60: 火力（ガス） | D60: 1 | E60: =VLOOKUP(C60,'[1]3'!$A$2:$D$11,3,FALSE) -> 170000 | F60: =VLOOKUP(C60,'[1]3'!$A$2:$D$11,4,FALSE) -> 12500 | G60: 104.77 | H60: =VLOOKUP(C60,'[1]3'!$A$2:$E$11,5,FALSE) -> 1 | I60: 0 | J60: 0 | K60: =K59 -> FALSE | L60: FALSE | M60: 0 | N60: 0 | O60: 35.703616 | P60: 135.96171
A61: 新大分発電所 | B61: 九州 | C61: 火力（ガス） | D61: 1 | E61: =VLOOKUP(C61,'[1]3'!$A$2:$D$11,3,FALSE) -> 170000 | F61: =VLOOKUP(C61,'[1]3'!$A$2:$D$11,4,FALSE) -> 12500 | G61: 2875 | H61: =VLOOKUP(C61,'[1]3'!$A$2:$E$11,5,FALSE) -> 1 | I61: 0 | J61: 0 | K61: =K60 -> FALSE | L61: FALSE | M61: 1 | N61: 1 | O61: 33.267981 | P61: 131.70689
... A106: 御坊発電所 | B106: 関西 | C106: 火力（石油） | D106: 1 | E106: =VLOOKUP(C106,'[1]3'!$A$2:$D$11,3,FALSE) -> 145000 | F106: =VLOOKUP(C106,'[1]3'!$A$2:$D$11,4,FALSE) -> 17500 | G106: 1800 | H106: =VLOOKUP(C106,'[1]3'!$A$2:$E$11,5,FALSE) -> 1 | I106: 0 | J106: 0 | K106: =K105 -> FALSE | L106: FALSE | M106: 1 | N106: 1 | O106: 33.859544 | P106: 135.15104
A107: 高浜発電所 | B107: 関西 | C107: 原子力 | D107: 1 | E107: =VLOOKUP(C107,'[1]3'!$A$2:$D$11,3,FALSE) -> 400000 | F107: =VLOOKUP(C107,'[1]3'!$A$2:$D$11,4,FALSE) -> 2000 | G107: 3392 | H107: 0.75 | I107: 0 | J107: 0 | K107: =K106 -> FALSE | L107: FALSE | M107: 0 | N107: 0 | O107: 35.522972 | P107: 135.50398
A108: 大飯発電所 | B108: 関西 | C108: 原子力 | D108: 1 | E108: =VLOOKUP(C108,'[1]3'!$A$2:$D$11,3,FALSE) -> 400000 | F108: =VLOOKUP(C108,'[1]3'!$A$2:$D$11,4,FALSE) -> 2000 | G108: 2360 | H108: =VLOOKUP(C108,'[1]3'!$A$2:$E$11,5,FALSE) -> 1 | I108: 0 | J108: 0 | K108: =K107 -> FALSE | L108: FALSE | M108: 0 | N108: 0 | O108: 35.541087 | P108: 135.65475
A109: 一般水力 北陸 | B109: 北陸 | C109: 水力 | D109: 1 | E109: =VLOOKUP(C109,'[1]3'!$A$2:$D$11,3,FALSE) -> 400000 | F109: =VLOOKUP(C109,'[1]3'!$A$2:$D$11,4,FALSE) -> 2000 | G109: 2152 | H109: =VLOOKUP(C109,'[1]3'!$A$2:$E$11,5,FALSE) -> 0.53 | I109: 0 | J109: 0 | K109: =K108 -> FALSE | L109: FALSE | M109: 1 | N109: 1 | O109: 36.299799 | P109: 137.10191
A110: 仙台パワーステーション | B110: 東北 | C110: 火力（石炭） | D110: 1 | E110: =VLOOKUP(C110,'[1]3'!$A$2:$D$11,3,FALSE) -> 270000 | F110: =VLOOKUP(C110,'[1]3'!$A$2:$D$11,4,FALSE) -> 8500 | G110: 112 | H110: =VLOOKUP(C110,'[1]3'!$A$2:$E$11,5,FALSE) -> 1 | I110: 0 | J110: 0 | K110: =K109 -> FALSE | L110: FALSE | M110: 0.6 | N110: 0.6 | O110: 38.268246 | P110: 141.00883
A111: 電源開発磯子火力発電所新２号機 | B111: 東京 | C111: 火力（石炭） | D111: 1 | E111: =VLOOKUP(C111,'[1]3'!$A$2:$D$11,3,FALSE) -> 270000 | F111: =VLOOKUP(C111,'[1]3'!$A$2:$D$11,4,FALSE) -> 8500 | G111: 600 | H111: =VLOOKUP(C111,'[1]3'!$A$2:$E$11,5,FALSE) -> 1 | I111: 0 | J111: 0 | K111: =K110 -> FALSE | L111: FALSE | M111: 0.6 | N111: 0.6 | O111: 35.403509 | P111: 139.64227
A112: ＪＦＥスチール株式会社川鉄千葉クリーンパワーステーション | B112: 東京 | C112: 火力（ガス） | D112: 1 | E112: =VLOOKUP(C112,'[1]3'!$A$2:$D$11,3,FALSE) -> 170000 | F112: =VLOOKUP(C112,'[1]3'!$A$2:$D$11,4,FALSE) -> 12500 | G112: 466.1 | H112: =VLOOKUP(C112,'[1]3'!$A$2:$E$11,5,FALSE) -> 1 | I112: 0 | J112: 0 | K112: =K111 -> FALSE | L112: FALSE | M112: 1 | N112: 1 | O112: 35.571517 | P112: 140.08733
A113: 浜岡原子力発電所 | B113: 中部 | C113: 原子力 | D113: 1 | E113: =VLOOKUP(C113,'[1]3'!$A$2:$D$11,3,FALSE) -> 400000 | F113: =VLOOKUP(C113,'[1]3'!$A$2:$D$11,4,FALSE) -> 2000 | G113: 3617 | H113: 0 | I113: 0 | J113: 0 | K113: =K112 -> FALSE | L113: FALSE | M113: 0 | N113: 0 | O113: 34.622653 | P113: 138.14677
A114: 一般水力 中部 | B114: 中部 | C114: 水力 | D114: 1 | E114: =VLOOKUP(C114,'[1]3'!$A$2:$D$11,3,FALSE) -> 400000 | F114: =VLOOKUP(C114,'[1]3'!$A$2:$D$11,4,FALSE) -> 2000 | G114: 4000 | H114: =VLOOKUP(C114,'[1]3'!$A$2:$E$11,5,FALSE) -> 0.53 | I114: 0 | J114: 0 | K114: =K113 -> FALSE | L114: FALSE | M114: 1 | N114: 1 | O114: 35.665979 | P114: 136.50175
A115: 四国電力 橘湾発電所 | B115: 関西 | C115: 火力（石炭） | D115: 1 | E115: =VLOOKUP(C115,'[1]3'!$A$2:$D$11,3,FALSE) -> 270000 | F115: =VLOOKUP(C115,'[1]3'!$A$2:$D$11,4,FALSE) -> 8500 | G115: 700 | H115: =VLOOKUP(C115,'[1]3'!$A$2:$E$11,5,FALSE) -> 1 | I115: 0 | J115: 0 | K115: =K114 -> FALSE | L115: FALSE | M115: 0.7 | N115: 0.7 | O115: 33.864348 | P115: 134.65566
...

Sheet temp
A1: 太陽光（北海道） | B1: 北海道 | C1: 太陽光 | D1: 1 | E1: 100000 | F1: 0 | G1: 1920 | H1: 1 | I1: 0 | J1: 0 | K1: FALSE | L1: FALSE | M1: 1 | N1: 1 | O1: 43.07 | P1: 141.4
A2: 太陽光（東北） | B2: 東北 | C2: 太陽光 | D2: 1 | E2: 100000 | F2: 0 | G2: 10410 | H2: 1 | I2: 0 | J2: 0 | K2: FALSE | L2: FALSE | M2: 1 | N2: 1 | O2: 38.28 | P2: 140.91
A3: 太陽光(東京) | B3: 東京 | C3: 太陽光 | D3: 1 | E3: 100000 | F3: 0 | G3: 16050 | H3: 1 | I3: 0 | J3: 0 | K3: FALSE | L3: FALSE | M3: 1 | N3: 1 | O3: 35.67 | P3: 139.82
A4: 太陽光(中部) | B4: 中部 | C4: 太陽光 | D4: 1 | E4: 100000 | F4: 0 | G4: 8020 | H4: 1 | I4: 0 | J4: 0 | K4: FALSE | L4: FALSE | M4: 1 | N4: 1 | O4: 35.18 | P4: 137.01
A5: 太陽光(北陸) | B5: 北陸 | C5: 太陽光 | D5: 1 | E5: 100000 | F5: 0 | G5: 920 | H5: 1 | I5: 0 | J5: 0 | K5: FALSE | L5: FALSE | M5: 1 | N5: 1 | O5: 36.7 | P5: 137.22
A6: 太陽光(関西) | B6: 関西 | C6: 太陽光 | D6: 1 | E6: 100000 | F6: 0 | G6: 5630 | H6: 1 | I6: 0 | J6: 0 | K6: FALSE | L6: FALSE | M6: 1 | N6: 1 | O6: 34.73 | P6: 135.95
A7: 太陽光(中国) | B7: 中国 | C7: 太陽光 | D7: 1 | E7: 100000 | F7: 0 | G7: 2310 | H7: 1 | I7: 0 | J7: 0 | K7: FALSE | L7: FALSE | M7: 1 | N7: 1 | O7: 34.39 | P7: 132.46
A8: 太陽光(四国) | B8: 四国 | C8: 太陽光 | D8: 1 | E8: 100000 | F8: 0 | G8: 5040 | H8: 1 | I8: 0 | J8: 0 | K8: FALSE | L8: FALSE | M8: 1 | N8: 1 | O8: 34.35 | P8: 134.05
A9: 太陽光(九州) | B9: 九州 | C9: 太陽光 | D9: 1 | E9: 100000 | F9: 0 | G9: 13220 | H9: 1 | I9: 0 | J9: 0 | K9: FALSE | L9: FALSE | M9: 1 | N9: 1 | O9: 33.58 | P9: 130.41

Sheet loads
A1: name | B1: bus
A2: 北海道D | B2: 北海道
A3: 東北D | B3: 東北
A4: 東京D | B4: 東京
A5: 中部D | B5: 中部
A6: 北陸D | B6: 北陸
A7: 関西D | B7: 関西
A8: 中国D | B8: 中国
A9: 四国D | B9: 四国
A10: 九州D | B10: 九州

Sheet Demand
A1: Date | B1: Day of week | C1: Week of year | D1: 北海道D | E1: 東北D | F1: 東京D | G1: 中部D | H1: 北陸D | I1: 関西D | J1: 中国D | K1: 四国D | L1: 九州D | M1: 沖縄D | N1: １０エリア計
A2: 45292 | B2: Saturday | C2: 1 | D2: 3811 | E2: 7471 | F2: 24024 | G2: 9991 | H2: 2465.4 | I2: 11820.484 | J2: 5159.022 | K2: 2290 | L2: 7918 | M2: 654.3 | N2: 75604.206
A3: 45292.042 | B3: Saturday | C3: 1 | D3: 3917 | E3: 7515 | F3: 22864 | G3: 9710 | H3: 2511.7 | I3: 11405.202 | J3: 5095.733 | K3: 2292 | L3: 7796 | M3: 633.6 | N3: 73740.235
A4: 45292.083 | B4: Saturday | C4: 1 | D4: 4019 | E4: 7659 | F4: 22433 | G4: 9807 | H4: 2678.1 | I4: 11581.15 | J4: 5283.915 | K4: 2440 | L4: 8129 | M4: 643.2 | N4: 74673.365
A5: 45292.125 | B5: Saturday | C5: 1 | D5: 4102 | E5: 7857 | F5: 22292 | G5: 9948 | H5: 2824 | I5: 11709.293 | J5: 5670.733 | K5: 2589 | L5: 8489 | M5: 667.5 | N5: 76148.526
A6: 45292.167 | B6: Saturday | C6: 1 | D6: 4118 | E6: 7991 | F6: 22294 | G6: 9937 | H6: 2848.5 | I6: 11598.002 | J6: 5766.22 | K6: 2638 | L6: 8643 | M6: 669.6 | N6: 76503.322
A7: 45292.208 | B7: Saturday | C7: 1 | D7: 4021 | E7: 7974 | F7: 22512 | G7: 9842 | H7: 2714.8 | I7: 11249.289 | J7: 5631.403 | K7: 2545 | L7: 8431 | M7: 652.8 | N7: 75573.292
A8: 45292.25 | B8: Saturday | C8: 1 | D8: 3864 | E8: 7796 | F8: 23209 | G8: 9772 | H8: 2490.2 | I8: 11094.319 | J8: 5406.099 | K8: 2312 | L8: 7953 | M8: 620.4 | N8: 74517.018
A9: 45292.292 | B9: Saturday | C9: 1 | D9: 3669 | E9: 7660 | F9: 24326 | G9: 10072 | H9: 2383.5 | I9: 11513.027 | J9: 5394.463 | K9: 2294 | L9: 7998 | M9: 625 | N9: 75934.99
A10: 45292.333 | B10: Saturday | C10: 1 | D10: 3622 | E10: 7710 | F10: 25153 | G10: 10513 | H10: 2422.3 | I10: 12301.712 | J10: 5503.535 | K10: 2459 | L10: 8096 | M10: 666.8 | N10: 78447.347
A11: 45292.375 | B11: Saturday | C11: 1 | D11: 3567 | E11: 7624 | F11: 24530 | G11: 10230 | H11: 2406.3 | I11: 12237.044 | J11: 5074.909 | K11: 2322 | L11: 7638 | M11: 680.544 | N11: 76309.797
A12: 45292.417 | B12: Saturday | C12: 1 | D12: 3482 | E12: 7453 | F12: 23842 | G12: 9788 | H12: 2351.1 | I12: 11857.735 | J12: 4628.737 | K12: 2240 | L12: 7445 | M12: 698.738 | N12: 73786.31
A13: 45292.458 | B13: Saturday | C13: 1 | D13: 3400 | E13: 7312 | F13: 23340 | G13: 9434 | H13: 2262.9 | I13: 11643.34 | J13: 4514.563 | K13: 2201 | L13: 7590 | M13: 706.043 | N13: 72403.846
... A8785: 45657.958 | B8785: Sunday | C8785: 53 | D8785: 4057 | E8785: 9089 | F8785: 28359 | G8785: 12085 | H8785: 2810.1 | I8785: 13761.775 | J8785: 5814.262 | K8785: 2714 | L8785: 9553 | M8785: 710.2 | N8785: 88953.337

Sheet stores
A1: name | B1: bus | C1: e_nom | D1: carrier
A2: 新冠 | B2: 新冠 | C2: 1600 | D2: 水
A3: 高見 | B3: 高見 | C3: 1712 | D3: 水
A4: 京極 | B4: 京極 | C4: 4800 | D4: 水
A5: 第二沼沢 | B5: 第二沼沢 | C5: 3680 | D5: 水
A6: 今市 | B6: 今市 | C6: 8400 | D6: 水
A7: 矢木沢 | B7: 矢木沢 | C7: 1920 | D7: 水
A8: 玉原 | B8: 玉原 | C8: 9600 | D8: 水
A9: 塩原 | B9: 塩原 | C9: 7200 | D9: 水
A10: 安曇 | B10: 安曇 | C10: 4984 | D10: 水
A11: 水殿 | B11: 水殿 | C11: 1960 | D11: 水
A12: 新高瀬川 | B12: 新高瀬川 | C12: 10240 | D12: 水
A13: 葛野川 | B13: 葛野川 | C13: 12800 | D13: 水
... A41: 小丸川 | B41: 小丸川 | C41: 9600 | D41: 水

Sheet 1
A1: name | B1: zone | C1: carrier | D1: x | E1: y
A2: １３４Ｔ（北大和線） | B2: 関西 | C2: AC | D2: 135.90046 | E2: 34.863572
A3: １７Ｔ（北大阪線） | B3: 関西 | C3: AC | D3: 135.51221 | E3: 34.879025
A4: ４２Ｔ（北神線） | B4: 関西 | C4: AC | D4: 135.16582 | E4: 34.813487
A5: 伊方原子力 | B5: 四国 | C5: AC | D5: 132.312 | E5: 33.491
A6: いわき変電所 | B6: 東北 | C6: AC | D6: 140.748 | E6: 36.989
A7: 柏崎刈羽原子力 | B7: 東京 | C7: AC | D7: 138.596 | E7: 37.4218
A8: 旧福島第二原子力 | B8: 東京 | C8: AC | D8: 141.025 | E8: 37.3168
A9: 舞鶴火力 | B9: 関西 | C9: AC | D9: 135.342 | E9: 35.5256
A10: 阿南変換所 | B10: 四国 | C10: AC | D10: 134.636 | E10: 33.8291
A11: 阿波変電所 | B11: 四国 | C11: AC | D11: 134.409 | E11: 34.0008
A12: 愛知変電所 | B12: 中部 | C12: AC | D12: 137.298 | E12: 35.2104
A13: 旭川変電所 | B13: 北海道 | C13: AC | D13: 142.353 | E13: 43.7715
... A26: 遠江変電所 | B26: 中部 | C26: AC | D26: 137.701 | E26: 34.8054
A27: 岡山幹線 | B27: 中国 | C27: AC | D27: #N/A | E27: #N/A
A28: 岡山変電所 | B28: 中国 | C28: AC | D28: 133.864 | E28: 34.7487
A29: 下広井変電所 | B29: 中部 | C29: AC | D29: 136.88939 | E29: 35.162872
A30: 加賀変電所 | B30: 北陸 | C30: AC | D30: 136.725 | E30: 36.5019
A31: 海崎変電所 | B31: 九州 | C31: AC | D31: 131.881 | E31: 32.9961
A32: 海部開閉所 | B32: 中部 | C32: AC | D32: 136.738 | E32: 35.1306
A33: 額田開閉所 | B33: 中部 | C33: AC | D33: 137.278 | E33: 34.9632
A34: 笠岡変電所 | B34: 中国 | C34: AC | D34: 133.518 | E34: 34.5323
A35: 葛南変電所 | B35: 東京 | C35: AC | D35: 139.908 | E35: 35.6658
A36: 苅田変電所 | B36: 九州 | C36: AC | D36: 130.995 | E36: 33.7891
A37: 岩手変電所 | B37: 東北 | C37: AC | D37: 141.176 | E37: 39.9051
A38: 岩清水開閉所 | B38: 北海道 | C38: AC | D38: 142.518 | E38: 42.5105
A39: 喜線山発電所 | B39: 関西 | C39: AC | D39: 135.858 | E39: 34.8959
... A62: 広見変電所 | B62: 四国 | C62: AC | D62: 132.687 | E62: 33.2466
A63: 広島西幹線 | B63: 中国 | C63: AC | D63: #N/A | E63: #N/A
A64: 広島中央変電所 | B64: 中国 | C64: AC | D64: 132.461 | E64: 34.3838
A65: 広島東幹線 | B65: 中国 | C65: AC | D65: #N/A | E65: #N/A
A66: 広島変電所 | B66: 中国 | C66: AC | D66: 132.538 | E66: 34.44
A67: 江東線 | B67: 東京 | C67: AC | D67: 139.90305 | E67: 35.669359
A68: 江東変電所 | B68: 東京 | C68: AC | D68: 139.84 | E68: 35.6632
A69: 港北線 | B69: 東京 | C69: AC | D69: #N/A | E69: #N/A
A70: 港北変電所 | B70: 東京 | C70: AC | D70: 139.603 | E70: 35.5359
A71: 甲賀変電所 | B71: 関西 | C71: AC | D71: 136.142 | E71: 35.0068
A72: 香川変電所 | B72: 四国 | C72: AC | D72: 134.003 | E72: 34.2258
A73: 高根変電所 | B73: 中部 | C73: AC | D73: 137.49349 | E73: 36.035871
A74: 高松変電所 | B74: 四国 | C74: AC | D74: 133.986 | E74: 34.29
...

Sheet 2
A1: Name | B1: carrier | C1: x | D1: y
A2: 新冠 | B2: 水 | C2: 142.59293 | D2: 42.617294
A3: 高見 | B3: 水 | C3: 142.63493 | D3: 42.456129
A4: 京極 | B4: 水 | C4: 140.95692 | D4: 42.959215
A5: 第二沼沢 | B5: 水 | C5: 139.60492 | D5: 37.454115
A6: 今市 | B6: 水 | C6: 139.68823 | D6: 36.835523
A7: 矢木沢 | B7: 水 | C7: 139.05674 | D7: 36.910952
A8: 玉原 | B8: 水 | C8: 139.03883 | D8: 36.805231
A9: 塩原 | B9: 水 | C9: 139.86883 | D9: 37.003263
A10: 安曇 | B10: 水 | C10: 137.72011 | D10: 36.133149
A11: 水殿 | B11: 水 | C11: 137.74791 | D11: 36.15474
A12: 新高瀬川 | B12: 水 | C12: 137.7208 | D12: 36.483346
A13: 葛野川 | B13: 水 | C13: 138.82167 | D13: 35.726558
... A41: 小丸川 | B41: 水 | C41: 131.39287 | D41: 32.250725

Sheet 4
A1: name | B1: bus | C1: e_nom | D1: carrier
A2: ='5'!C2 -> 新冠 | B2: =A2 -> 新冠 | C2: ='5'!D2 -> 1.6 | D2: 水
A3: ='5'!C3 -> 高見 | B3: =A3 -> 高見 | C3: ='5'!D3 -> 1.712 | D3: 水
A4: ='5'!C4 -> 京極 | B4: =A4 -> 京極 | C4: ='5'!D4 -> 4.8 | D4: 水
A5: ='5'!C5 -> 第二沼沢 | B5: =A5 -> 第二沼沢 | C5: ='5'!D5 -> 3.68 | D5: 水
A6: ='5'!C6 -> 今市 | B6: =A6 -> 今市 | C6: ='5'!D6 -> 8.4 | D6: 水
A7: ='5'!C7 -> 矢木沢 | B7: =A7 -> 矢木沢 | C7: ='5'!D7 -> 1.92 | D7: 水
A8: ='5'!C8 -> 玉原 | B8: =A8 -> 玉原 | C8: ='5'!D8 -> 9.6 | D8: 水
A9: ='5'!C9 -> 塩原 | B9: =A9 -> 塩原 | C9: ='5'!D9 -> 7.2 | D9: 水
A10: ='5'!C10 -> 安曇 | B10: =A10 -> 安曇 | C10: ='5'!D10 -> 4.984 | D10: 水
A11: ='5'!C11 -> 水殿 | B11: =A11 -> 水殿 | C11: ='5'!D11 -> 1.96 | D11: 水
A12: ='5'!C12 -> 新高瀬川 | B12: =A12 -> 新高瀬川 | C12: ='5'!D12 -> 10.24 | D12: 水
A13: ='5'!C13 -> 葛野川 | B13: =A13 -> 葛野川 | C13: ='5'!D13 -> 12.8 | D13: 水
... A41: ='5'!C41 -> 小丸川 | B41: =A41 -> 小丸川 | C41: ='5'!D41 -> 9.6 | D41: 水

Sheet 6
A1: Name | B1: carrier | C1: bus0 | D1: bus1 | E1: p_nom | F1: p_min_pu | G1: p_max_pu | H1: committable | I1: marginal_cost | J1: ramp_limit_down | K1: ramp_limit_up | L1: start_up_cost
A2: ='5'!C2 -> 新冠 | B2: 揚水 | C2: 新冠 | D2: 北海道 | E2: 200 | F2: 0 | G2: 1 | H2: "True" | J2: 0.1 | K2: 0.1 | L2: 100
A3: ='5'!C3 -> 高見 | B3: 揚水 | C3: 高見 | D3: 北海道 | E3: 200 | F3: 0 | G3: 1 | H3: "True" | J3: 0.1 | K3: 0.1 | L3: 100
A4: ='5'!C4 -> 京極 | B4: 揚水 | C4: 京極 | D4: 北海道 | E4: 400 | F4: 0 | G4: 1 | H4: "True" | J4: 0.1 | K4: 0.1 | L4: 100
A5: ='5'!C5 -> 第二沼沢 | B5: 揚水 | C5: 第二沼沢 | D5: 東北 | E5: 460 | F5: 0 | G5: 1 | H5: "True" | J5: 0.1 | K5: 0.1 | L5: 100
A6: ='5'!C6 -> 今市 | B6: 揚水 | C6: 今市 | D6: 東京 | E6: 1050 | F6: 0 | G6: 1 | H6: "True" | J6: 0.1 | K6: 0.1 | L6: 100
A7: ='5'!C7 -> 矢木沢 | B7: 揚水 | C7: 矢木沢 | D7: 東京 | E7: 240 | F7: 0 | G7: 1 | H7: "True" | J7: 0.1 | K7: 0.1 | L7: 100
A8: ='5'!C8 -> 玉原 | B8: 揚水 | C8: 玉原 | D8: 東京 | E8: 1200 | F8: 0 | G8: 1 | H8: "True" | J8: 0.1 | K8: 0.1 | L8: 100
A9: ='5'!C9 -> 塩原 | B9: 揚水 | C9: 塩原 | D9: 東京 | E9: 900 | F9: 0 | G9: 1 | H9: "True" | J9: 0.1 | K9: 0.1 | L9: 100
A10: ='5'!C10 -> 安曇 | B10: 揚水 | C10: 安曇 | D10: 東京 | E10: 623 | F10: 0 | G10: 1 | H10: "True" | J10: 0.1 | K10: 0.1 | L10: 100
A11: ='5'!C11 -> 水殿 | B11: 揚水 | C11: 水殿 | D11: 東京 | E11: 163 | F11: 0 | G11: 1 | H11: "True" | J11: 0.1 | K11: 0.1 | L11: 100
A12: ='5'!C12 -> 新高瀬川 | B12: 揚水 | C12: 新高瀬川 | D12: 東京 | E12: 1280 | F12: 0 | G12: 1 | H12: "True" | J12: 0.1 | K12: 0.1 | L12: 100
A13: ='5'!C13 -> 葛野川 | B13: 揚水 | C13: 葛野川 | D13: 東京 | E13: 1200 | F13: 0 | G13: 1 | H13: "True" | J13: 0.1 | K13: 0.1 | L13: 100
... A41: ='5'!C41 -> 小丸川 | B41: 揚水 | C41: 小丸川 | D41: 九州 | E41: 1200 | F41: 0 | G41: 1 | H41: "True" | J41: 0.1 | K41: 0.1 | L41: 100

Sheet 5
A1: Reservoir ID No | B1: Name | C1: 和名 | D1: Capacity [GWh]
A2: 0 | B2: NIIKAP | C2: 新冠 | D2: 1.6
A3: 1 | B3: TAKAMI | C3: 高見 | D3: 1.712
A4: 2 | B4: KYOUGO | C4: 京極 | D4: 4.8
A5: 3 | B5: NUMAZ2 | C5: 第二沼沢 | D5: 3.68
A6: 4 | B6: IMAICH | C6: 今市 | D6: 8.4
A7: 5 | B7: YAGISA | C7: 矢木沢 | D7: 1.92
A8: 6 | B8: TAMAHA | C8: 玉原 | D8: 9.6
A9: 7 | B9: SHIOBA | C9: 塩原 | D9: 7.2
A10: 8 | B10: AZUMI | C10: 安曇 | D10: 4.984
A11: 9 | B11: MIDONO | C11: 水殿 | D11: 1.96
A12: 10 | B12: STAKAS | C12: 新高瀬川 | D12: 10.24
A13: 11 | B13: KATU | C13: 葛野川 | D13: 12.8
... A41: 39 | B41: OMARU | C41: 小丸川 | D41: 9.6

Sheet 7
A1: =ROWS(SN) -> 118 | C1: Node | D1: Type | E1: Name | F1: Device Type | G1: Unit Capacity [GW/unit] | H1: Maximum Capacity | I1: Cycle Efficiency | J1: Reservoirs No | K1: 貯水池名 | L1: Minimum Output Rate | M1: Minimum Input Rate | N1: LFC regulation Rate | O1: Synchronous Inertia [s] | P1: Maximum Unit Number | Q1: Exsiting Unit Number
B2: msb | C2: =VLOOKUP(B2,[2]SYS!$F$5:$G$361,2,FALSE) -> 3 | D2: Pumped | E2: 1NIIKAP1 | F2: 0 | G2: 0.1 | H2: 1 | I2: 0.7 | J2: 0 | K2: =VLOOKUP(J2,[3]Reservoirs!B$2:D$41,3,FALSE) -> 新冠 | L2: 0.5 | M2: 0.99 | N2: 0.2 | O2: 10 | P2: 1 | Q2: 1
B3: msb | C3: =VLOOKUP(B3,[2]SYS!$F$5:$G$361,2,FALSE) -> 3 | D3: Pumped | E3: 1NIIKAP2 | F3: 0 | G3: 0.1 | H3: 1 | I3: 0.7 | J3: 0 | K3: =VLOOKUP(J3,[3]Reservoirs!B$2:D$41,3,FALSE) -> 新冠 | L3: 0.5 | M3: 0.99 | N3: 0.2 | O3: 10 | P3: 1 | Q3: 1
B4: msb | C4: =VLOOKUP(B4,[2]SYS!$F$5:$G$361,2,FALSE) -> 3 | D4: Pumped | E4: 1TAKAMI1 | F4: 0 | G4: 0.1 | H4: 1 | I4: 0.7 | J4: 1 | K4: =VLOOKUP(J4,[3]Reservoirs!B$2:D$41,3,FALSE) -> 高見 | L4: 0.5 | M4: 0.99 | N4: 0.2 | O4: 10 | P4: 1 | Q4: 1
B5: msb | C5: =VLOOKUP(B5,[2]SYS!$F$5:$G$361,2,FALSE) -> 3 | D5: Pumped | E5: 1TAKAM2U | F5: 0 | G5: 0.114 | H5: 1 | I5: 0.7 | J5: 1 | K5: =VLOOKUP(J5,[3]Reservoirs!B$2:D$41,3,FALSE) -> 高見 | L5: 0.5 | M5: 0.55 | N5: 0.2 | O5: 0 | P5: 1 | Q5: 1
B6: nno | C6: =VLOOKUP(B6,[2]SYS!$F$5:$G$361,2,FALSE) -> 1 | D6: Pumped | E6: 1KYOUGO1 | F6: 0 | G6: 0.2 | H6: 1 | I6: 0.7 | J6: 2 | K6: =VLOOKUP(J6,[3]Reservoirs!B$2:D$41,3,FALSE) -> 京極 | L6: 0.5 | M6: 0.6 | N6: 0.2 | O6: 0 | P6: 1 | Q6: 1
B7: nno | C7: =VLOOKUP(B7,[2]SYS!$F$5:$G$361,2,FALSE) -> 1 | D7: Pumped | E7: 1KYOUGO2 | F7: 0 | G7: 0.2 | H7: 1 | I7: 0.7 | J7: 2 | K7: =VLOOKUP(J7,[3]Reservoirs!B$2:D$41,3,FALSE) -> 京極 | L7: 0.5 | M7: 0.6 | N7: 0.2 | O7: 0 | P7: 1 | Q7: 1
B8: nno | C8: =VLOOKUP(B8,[2]SYS!$F$5:$G$361,2,FALSE) -> 1 | D8: Pumped | E8: 1KYOUGO3 | F8: 0 | G8: 0.2 | H8: 1 | I8: 0.7 | J8: 2 | K8: =VLOOKUP(J8,[3]Reservoirs!B$2:D$41,3,FALSE) -> 京極 | L8: 0.5 | M8: 0.6 | N8: 0.2 | O8: 0 | P8: 1 | Q8: 1
B9: hnn | C9: =VLOOKUP(B9,[2]SYS!$F$5:$G$361,2,FALSE) -> 55 | D9: Pumped | E9: 2NUMAZ21 | F9: 0 | G9: 0.23 | H9: 1 | I9: 0.7 | J9: 3 | K9: =VLOOKUP(J9,[3]Reservoirs!B$2:D$41,3,FALSE) -> 第二沼沢 | L9: 0.5 | M9: 0.99 | N9: 0.2 | O9: 10 | P9: 1 | Q9: 1
B10: hnn | C10: =VLOOKUP(B10,[2]SYS!$F$5:$G$361,2,FALSE) -> 55 | D10: Pumped | E10: 2NUMAZ22 | F10: 0 | G10: 0.23 | H10: 1 | I10: 0.7 | J10: 3 | K10: =VLOOKUP(J10,[3]Reservoirs!B$2:D$41,3,FALSE) -> 第二沼沢 | L10: 0.5 | M10: 0.99 | N10: 0.2 | O10: 10 | P10: 1 | Q10: 1
B11: sii | C11: =VLOOKUP(B11,[2]SYS!$F$5:$G$361,2,FALSE) -> 66 | D11: Pumped | E11: 3IMAICH1 | F11: 0 | G11: 0.35 | H11: 1 | I11: 0.7 | J11: 4 | K11: =VLOOKUP(J11,[3]Reservoirs!B$2:D$41,3,FALSE) -> 今市 | L11: 0.5 | M11: 0.99 | N11: 0.2 | O11: 10 | P11: 1 | Q11: 1
B12: sii | C12: =VLOOKUP(B12,[2]SYS!$F$5:$G$361,2,FALSE) -> 66 | D12: Pumped | E12: 3IMAICH2 | F12: 0 | G12: 0.35 | H12: 1 | I12: 0.7 | J12: 4 | K12: =VLOOKUP(J12,[3]Reservoirs!B$2:D$41,3,FALSE) -> 今市 | L12: 0.5 | M12: 0.99 | N12: 0.2 | O12: 10 | P12: 1 | Q12: 1
B13: sii | C13: =VLOOKUP(B13,[2]SYS!$F$5:$G$361,2,FALSE) -> 66 | D13: Pumped | E13: 3IMAICH3 | F13: 0 | G13: 0.35 | H13: 1 | I13: 0.7 | J13: 4 | K13: =VLOOKUP(J13,[3]Reservoirs!B$2:D$41,3,FALSE) -> 今市 | L13: 0.5 | M13: 0.99 | N13: 0.2 | O13: 10 | P13: 1 | Q13: 1
... B119: myz | C119: =VLOOKUP(B119,[2]SYS!$F$5:$G$361,2,FALSE) -> 316 | D119: Pumped | E119: 9OMARU4 | F119: 0 | G119: 0.3 | H119: 1 | I119: 0.7 | J119: 39 | K119: =VLOOKUP(J119,[3]Reservoirs!B$2:D$41,3,FALSE) -> 小丸川 | L119: 0.5 | M119: 0.6 | N119: 0.2 | O119: 0 | P119: 1 | Q119: 1

Sheet 8
A1: 北陸電力 有峰第二発電所 | B1: 北陸 | C1: 水力 | D1: 1 | E1: 400000 | F1: 2000 | G1: 123 | H1: 0.53 | I1: 0 | J1: 0 | K1: FALSE | L1: false | M1: 1 | N1: 1 | O1: 36.54806 | P1: 137.37114
A2: 音沢発電所 | B2: 北陸 | C2: 水力 | D2: 1 | E2: 400000 | F2: 2000 | G2: 124 | H2: 0.53 | I2: 0 | J2: 0 | K2: FALSE | L2: false | M2: 1 | N2: 1 | O2: 26.332815 | P2: 126.77243
A3: 木曽発電所 | B3: 中部 | C3: 水力 | D3: 1 | E3: 400000 | F3: 2000 | G3: 116 | H3: 0.53 | I3: 0 | J3: 0 | K3: FALSE | L3: false | M3: 1 | N3: 1 | O3: 35.819864 | P3: 137.6788
A4: 下小鳥発電所 | B4: 中部 | C4: 水力 | D4: 1 | E4: 400000 | F4: 2000 | G4: 142 | H4: 0.53 | I4: 0 | J4: 0 | K4: FALSE | L4: false | M4: 1 | N4: 1 | O4: 36.299799 | P4: 137.10191
A5: 徳山発電所 | B5: 中部 | C5: 水力 | D5: 1 | E5: 400000 | F5: 2000 | G5: 164.2 | H5: 0.53 | I5: 0 | J5: 0 | K5: FALSE | L5: false | M5: 1 | N5: 1 | O5: 35.665979 | P5: 136.50175
A6: 小千谷第二発電所 | B6: 中部 | C6: 水力 | D6: 1 | E6: 400000 | F6: 2000 | G6: 206 | H6: 0.53 | I6: 0 | J6: 0 | K6: FALSE | L6: false | M6: 1 | N6: 1 | O6: 37.293925 | P6: 138.80936
A7: 北陸電力 有峰第一発電所 | B7: 北陸 | C7: 水力 | D7: 1 | E7: 400000 | F7: 2000 | G7: 265 | H7: 0.53 | I7: 0 | J7: 0 | K7: FALSE | L7: false | M7: 1 | N7: 1 | O7: 36.537259 | P7: 137.43911
A8: 田子倉発電所 | B8: 東北 | C8: 水力 | D8: 1 | E8: 400000 | F8: 2000 | G8: 400 | H8: 0.53 | I8: 0 | J8: 0 | K8: FALSE | L8: false | M8: 1 | N8: 1 | O8: 37.312162 | P8: 139.29219
A9: 奥只見発電所 | B9: 東北 | C9: 水力 | D9: 1 | E9: 400000 | F9: 2000 | G9: 560 | H9: 0.53 | I9: 0 | J9: 0 | K9: FALSE | L9: false | M9: 1 | N9: 1 | O9: 37.154785 | P9: 139.24957
